Workbook

Sheet Content Map
A1: # | B1: Old URL | C1: Page type | D1: Suggested action | E1: Agreed action | F1: Working action | G1: Notes | H1: 12m clicks (GSC) | I1: 12m views (GA4) | J1: New URL | K1: Owner | L1: Claire sign-off | M1: Status | N1: Redirect set up
A2: 1 | B2: https://www.lipid.co.uk/ | C2: Landing page | D2: Rewrite | F2: =IF(B2="","",IF(E2<>"",E2,D2)) -> Rewrite | G2: Becomes the MLA landing page in the Hutton structure. Rebuild from the Hutton template. | H2: =IF($B2="","",IFERROR(INDEX(GSC!$B:$B,MATCH($B2,GSC!$A:$A,0)),0)) -> 257 | I2: =IF($B2="","",IFERROR(INDEX('GA4'!$B:$B,MATCH(SUBSTITUTE($B2,"https://www.lipid.co.uk",""),'GA4'!$A:$A,0)),0)) -> 2698 | M2: Not started | N2: No
A3: 2 | B3: https://www.lipid.co.uk/about-us | C3: Information page | D3: Rewrite | F3: =IF(B3="","",IF(E3<>"",E3,D3)) -> Rewrite | G3: Core page. Rewrite for Hutton tone and merge in company history. | H3: =IF($B3="","",IFERROR(INDEX(GSC!$B:$B,MATCH($B3,GSC!$A:$A,0)),0)) -> 43 | I3: =IF($B3="","",IFERROR(INDEX('GA4'!$B:$B,MATCH(SUBSTITUTE($B3,"https://www.lipid.co.uk",""),'GA4'!$A:$A,0)),0)) -> 274 | M3: Not started | N3: No
A4: 3 | B4: https://www.lipid.co.uk/james-hutton-limited | C4: Information page | D4: Retire | F4: =IF(B4="","",IF(E4<>"",E4,D4)) -> Retire | G4: Fold into the About page or the Hutton corporate pages. | H4: =IF($B4="","",IFERROR(INDEX(GSC!$B:$B,MATCH($B4,GSC!$A:$A,0)),0)) -> 7 | I4: =IF($B4="","",IFERROR(INDEX('GA4'!$B:$B,MATCH(SUBSTITUTE($B4,"https://www.lipid.co.uk",""),'GA4'!$A:$A,0)),0)) -> 67 | M4: Not started | N4: No
A5: 4 | B5: https://www.lipid.co.uk/quality | C5: Information page | D5: Rewrite | F5: =IF(B5="","",IF(E5<>"",E5,D5)) -> Rewrite | G5: Key trust page (accreditations, proficiency testing). Claire to check accuracy. | H5: =IF($B5="","",IFERROR(INDEX(GSC!$B:$B,MATCH($B5,GSC!$A:$A,0)),0)) -> 1 | I5: =IF($B5="","",IFERROR(INDEX('GA4'!$B:$B,MATCH(SUBSTITUTE($B5,"https://www.lipid.co.uk",""),'GA4'!$A:$A,0)),0)) -> 137 | M5: Not started | N5: No
A6: 5 | B6: https://www.lipid.co.uk/samples | C6: Information page | D6: Rewrite | F6: =IF(B6="","",IF(E6<>"",E6,D6)) -> Rewrite | G6: Sample submission guidance is high value. Check downloads and forms attached. | H6: =IF($B6="","",IFERROR(INDEX(GSC!$B:$B,MATCH($B6,GSC!$A:$A,0)),0)) -> 1 | I6: =IF($B6="","",IFERROR(INDEX('GA4'!$B:$B,MATCH(SUBSTITUTE($B6,"https://www.lipid.co.uk",""),'GA4'!$A:$A,0)),0)) -> 118 | M6: Not started | N6: No
A7: 6 | B7: https://www.lipid.co.uk/services/lipid-analysis/meet-team | C7: Information page | D7: Merge | F7: =IF(B7="","",IF(E7<>"",E7,D7)) -> Merge | G7: Merge into the team or About section. | H7: =IF($B7="","",IFERROR(INDEX(GSC!$B:$B,MATCH($B7,GSC!$A:$A,0)),0)) -> 1 | I7: =IF($B7="","",IFERROR(INDEX('GA4'!$B:$B,MATCH(SUBSTITUTE($B7,"https://www.lipid.co.uk",""),'GA4'!$A:$A,0)),0)) -> 62 | M7: Not started | N7: No
A8: 7 | B8: https://www.lipid.co.uk/testimonials | C8: Information page | D8: Rewrite | F8: =IF(B8="","",IF(E8<>"",E8,D8)) -> Rewrite | G8: Merge in the testimonials carousel slide. Check permission to keep quotes. | H8: =IF($B8="","",IFERROR(INDEX(GSC!$B:$B,MATCH($B8,GSC!$A:$A,0)),0)) -> 4 | I8: =IF($B8="","",IFERROR(INDEX('GA4'!$B:$B,MATCH(SUBSTITUTE($B8,"https://www.lipid.co.uk",""),'GA4'!$A:$A,0)),0)) -> 73 | M8: Not started | N8: No
A9: 8 | B9: https://www.lipid.co.uk/useful-links | C9: Information page | D9: Retire | F9: =IF(B9="","",IF(E9<>"",E9,D9)) -> Retire | G9: Check links still work and whether Hutton would host a links page at all. | H9: =IF($B9="","",IFERROR(INDEX(GSC!$B:$B,MATCH($B9,GSC!$A:$A,0)),0)) -> 0 | I9: =IF($B9="","",IFERROR(INDEX('GA4'!$B:$B,MATCH(SUBSTITUTE($B9,"https://www.lipid.co.uk",""),'GA4'!$A:$A,0)),0)) -> 46 | M9: Not started | N9: No
A10: 9 | B10: https://www.lipid.co.uk/services | C10: Service page | D10: Rewrite | F10: =IF(B10="","",IF(E10<>"",E10,D10)) -> Rewrite | G10: Core commercial page. Prioritise. | H10: =IF($B10="","",IFERROR(INDEX(GSC!$B:$B,MATCH($B10,GSC!$A:$A,0)),0)) -> 4 | I10: =IF($B10="","",IFERROR(INDEX('GA4'!$B:$B,MATCH(SUBSTITUTE($B10,"https://www.lipid.co.uk",""),'GA4'!$A:$A,0)),0)) -> 372 | M10: Not started | N10: No
A11: 10 | B11: https://www.lipid.co.uk/services/analyses | C11: Service page | D11: Rewrite | F11: =IF(B11="","",IF(E11<>"",E11,D11)) -> Rewrite | G11: Core commercial page. Prioritise. | H11: =IF($B11="","",IFERROR(INDEX(GSC!$B:$B,MATCH($B11,GSC!$A:$A,0)),0)) -> 16 | I11: =IF($B11="","",IFERROR(INDEX('GA4'!$B:$B,MATCH(SUBSTITUTE($B11,"https://www.lipid.co.uk",""),'GA4'!$A:$A,0)),0)) -> 227 | M11: Not started | N11: No
A12: 11 | B12: https://www.lipid.co.uk/services/method-development-validation | C12: Service page | D12: Rewrite | F12: =IF(B12="","",IF(E12<>"",E12,D12)) -> Rewrite | G12: Core commercial page. Prioritise. | H12: =IF($B12="","",IFERROR(INDEX(GSC!$B:$B,MATCH($B12,GSC!$A:$A,0)),0)) -> 2 | I12: =IF($B12="","",IFERROR(INDEX('GA4'!$B:$B,MATCH(SUBSTITUTE($B12,"https://www.lipid.co.uk",""),'GA4'!$A:$A,0)),0)) -> 65 | M12: Not started | N12: No
A13: 12 | B13: https://www.lipid.co.uk/services/stability | C13: Service page | D13: Rewrite | F13: =IF(B13="","",IF(E13<>"",E13,D13)) -> Rewrite | G13: Suggested pilot page: representative, commercial and easy to review. | H13: =IF($B13="","",IFERROR(INDEX(GSC!$B:$B,MATCH($B13,GSC!$A:$A,0)),0)) -> 2 | I13: =IF($B13="","",IFERROR(INDEX('GA4'!$B:$B,MATCH(SUBSTITUTE($B13,"https://www.lipid.co.uk",""),'GA4'!$A:$A,0)),0)) -> 31 | M13: Not started | N13: No
... A126: 125 | B126: https://www.lipid.co.uk/test-slide-page | C126: Test / duplicate | D126: Retire | F126: =IF(B126="","",IF(E126<>"",E126,D126)) -> Retire | G126: Looks like a test page. Retire. | H126: =IF($B126="","",IFERROR(INDEX(GSC!$B:$B,MATCH($B126,GSC!$A:$A,0)),0)) -> 0 | I126: =IF($B126="","",IFERROR(INDEX('GA4'!$B:$B,MATCH(SUBSTITUTE($B126,"https://www.lipid.co.uk",""),'GA4'!$A:$A,0)),0)) -> 0 | M126: Not started | N126: No
F127: =IF(B127="","",IF(E127<>"",E127,D127)) | H127: =IF($B127="","",IFERROR(INDEX(GSC!$B:$B,MATCH($B127,GSC!$A:$A,0)),0)) | I127: =IF($B127="","",IFERROR(INDEX('GA4'!$B:$B,MATCH(SUBSTITUTE($B127,"https://www.lipid.co.uk",""),'GA4'!$A:$A,0)),0))
F128: =IF(B128="","",IF(E128<>"",E128,D128)) | H128: =IF($B128="","",IFERROR(INDEX(GSC!$B:$B,MATCH($B128,GSC!$A:$A,0)),0)) | I128: =IF($B128="","",IFERROR(INDEX('GA4'!$B:$B,MATCH(SUBSTITUTE($B128,"https://www.lipid.co.uk",""),'GA4'!$A:$A,0)),0))
F129: =IF(B129="","",IF(E129<>"",E129,D129)) | H129: =IF($B129="","",IFERROR(INDEX(GSC!$B:$B,MATCH($B129,GSC!$A:$A,0)),0)) | I129: =IF($B129="","",IFERROR(INDEX('GA4'!$B:$B,MATCH(SUBSTITUTE($B129,"https://www.lipid.co.uk",""),'GA4'!$A:$A,0)),0))
F130: =IF(B130="","",IF(E130<>"",E130,D130)) | H130: =IF($B130="","",IFERROR(INDEX(GSC!$B:$B,MATCH($B130,GSC!$A:$A,0)),0)) | I130: =IF($B130="","",IFERROR(INDEX('GA4'!$B:$B,MATCH(SUBSTITUTE($B130,"https://www.lipid.co.uk",""),'GA4'!$A:$A,0)),0))
F131: =IF(B131="","",IF(E131<>"",E131,D131)) | H131: =IF($B131="","",IFERROR(INDEX(GSC!$B:$B,MATCH($B131,GSC!$A:$A,0)),0)) | I131: =IF($B131="","",IFERROR(INDEX('GA4'!$B:$B,MATCH(SUBSTITUTE($B131,"https://www.lipid.co.uk",""),'GA4'!$A:$A,0)),0))
F132: =IF(B132="","",IF(E132<>"",E132,D132)) | H132: =IF($B132="","",IFERROR(INDEX(GSC!$B:$B,MATCH($B132,GSC!$A:$A,0)),0)) | I132: =IF($B132="","",IFERROR(INDEX('GA4'!$B:$B,MATCH(SUBSTITUTE($B132,"https://www.lipid.co.uk",""),'GA4'!$A:$A,0)),0))
F133: =IF(B133="","",IF(E133<>"",E133,D133)) | H133: =IF($B133="","",IFERROR(INDEX(GSC!$B:$B,MATCH($B133,GSC!$A:$A,0)),0)) | I133: =IF($B133="","",IFERROR(INDEX('GA4'!$B:$B,MATCH(SUBSTITUTE($B133,"https://www.lipid.co.uk",""),'GA4'!$A:$A,0)),0))
F134: =IF(B134="","",IF(E134<>"",E134,D134)) | H134: =IF($B134="","",IFERROR(INDEX(GSC!$B:$B,MATCH($B134,GSC!$A:$A,0)),0)) | I134: =IF($B134="","",IFERROR(INDEX('GA4'!$B:$B,MATCH(SUBSTITUTE($B134,"https://www.lipid.co.uk",""),'GA4'!$A:$A,0)),0))
F135: =IF(B135="","",IF(E135<>"",E135,D135)) | H135: =IF($B135="","",IFERROR(INDEX(GSC!$B:$B,MATCH($B135,GSC!$A:$A,0)),0)) | I135: =IF($B135="","",IFERROR(INDEX('GA4'!$B:$B,MATCH(SUBSTITUTE($B135,"https://www.lipid.co.uk",""),'GA4'!$A:$A,0)),0))
F136: =IF(B136="","",IF(E136<>"",E136,D136)) | H136: =IF($B136="","",IFERROR(INDEX(GSC!$B:$B,MATCH($B136,GSC!$A:$A,0)),0)) | I136: =IF($B136="","",IFERROR(INDEX('GA4'!$B:$B,MATCH(SUBSTITUTE($B136,"https://www.lipid.co.uk",""),'GA4'!$A:$A,0)),0))
F137: =IF(B137="","",IF(E137<>"",E137,D137)) | H137: =IF($B137="","",IFERROR(INDEX(GSC!$B:$B,MATCH($B137,GSC!$A:$A,0)),0)) | I137: =IF($B137="","",IFERROR(INDEX('GA4'!$B:$B,MATCH(SUBSTITUTE($B137,"https://www.lipid.co.uk",""),'GA4'!$A:$A,0)),0))
F138: =IF(B138="","",IF(E138<>"",E138,D138)) | H138: =IF($B138="","",IFERROR(INDEX(GSC!$B:$B,MATCH($B138,GSC!$A:$A,0)),0)) | I138: =IF($B138="","",IFERROR(INDEX('GA4'!$B:$B,MATCH(SUBSTITUTE($B138,"https://www.lipid.co.uk",""),'GA4'!$A:$A,0)),0))
... F150: =IF(B150="","",IF(E150<>"",E150,D150)) | H150: =IF($B150="","",IFERROR(INDEX(GSC!$B:$B,MATCH($B150,GSC!$A:$A,0)),0)) | I150: =IF($B150="","",IFERROR(INDEX('GA4'!$B:$B,MATCH(SUBSTITUTE($B150,"https://www.lipid.co.uk",""),'GA4'!$A:$A,0)),0))

Sheet Summary
A1: MLA to Hutton migration: summary
A2: All figures update automatically from the Content Map tab.
A4: Total pages listed | B4: =COUNTA('Content Map'!$B$2:$B$150) -> 125
A5: Actions agreed so far | B5: =COUNTA('Content Map'!$E$2:$E$150) -> 0
A6: Agreed as % of pages | B6: =IF(B4=0,0,B5/B4) -> 0
A8: Working action | B8: Pages | C8: % of total
A9: Migrate as is | B9: =COUNTIF('Content Map'!$F$2:$F$150,A9) -> 13 | C9: =IF($B$4=0,0,B9/$B$4) -> 0.104
A10: Rewrite | B10: =COUNTIF('Content Map'!$F$2:$F$150,A10) -> 36 | C10: =IF($B$4=0,0,B10/$B$4) -> 0.288
A11: Merge | B11: =COUNTIF('Content Map'!$F$2:$F$150,A11) -> 10 | C11: =IF($B$4=0,0,B11/$B$4) -> 0.08
A12: Retire | B12: =COUNTIF('Content Map'!$F$2:$F$150,A12) -> 66 | C12: =IF($B$4=0,0,B12/$B$4) -> 0.528
A13: Review | B13: =COUNTIF('Content Map'!$F$2:$F$150,A13) -> 0 | C13: =IF($B$4=0,0,B13/$B$4) -> 0
A14: Total | B14: =SUM(B9:B13) -> 125 | C14: =SUM(C9:C13) -> 1
A16: Page type | B16: Migrate as is | C16: Rewrite | D16: Merge | E16: Retire | F16: Review | G16: Total
A17: Landing page | B17: =COUNTIFS('Content Map'!$C$2:$C$150,$A17,'Content Map'!$F$2:$F$150,B$16) -> 0 | C17: =COUNTIFS('Content Map'!$C$2:$C$150,$A17,'Content Map'!$F$2:$F$150,C$16) -> 1 | D17: =COUNTIFS('Content Map'!$C$2:$C$150,$A17,'Content Map'!$F$2:$F$150,D$16) -> 0 | E17: =COUNTIFS('Content Map'!$C$2:$C$150,$A17,'Content Map'!$F$2:$F$150,E$16) -> 0 | F17: =COUNTIFS('Content Map'!$C$2:$C$150,$A17,'Content Map'!$F$2:$F$150,F$16) -> 0 | G17: =SUM(B17:F17) -> 1
A18: Information page | B18: =COUNTIFS('Content Map'!$C$2:$C$150,$A18,'Content Map'!$F$2:$F$150,B$16) -> 0 | C18: =COUNTIFS('Content Map'!$C$2:$C$150,$A18,'Content Map'!$F$2:$F$150,C$16) -> 4 | D18: =COUNTIFS('Content Map'!$C$2:$C$150,$A18,'Content Map'!$F$2:$F$150,D$16) -> 1 | E18: =COUNTIFS('Content Map'!$C$2:$C$150,$A18,'Content Map'!$F$2:$F$150,E$16) -> 2 | F18: =COUNTIFS('Content Map'!$C$2:$C$150,$A18,'Content Map'!$F$2:$F$150,F$16) -> 0 | G18: =SUM(B18:F18) -> 7
A19: Service page | B19: =COUNTIFS('Content Map'!$C$2:$C$150,$A19,'Content Map'!$F$2:$F$150,B$16) -> 0 | C19: =COUNTIFS('Content Map'!$C$2:$C$150,$A19,'Content Map'!$F$2:$F$150,C$16) -> 4 | D19: =COUNTIFS('Content Map'!$C$2:$C$150,$A19,'Content Map'!$F$2:$F$150,D$16) -> 0 | E19: =COUNTIFS('Content Map'!$C$2:$C$150,$A19,'Content Map'!$F$2:$F$150,E$16) -> 0 | F19: =COUNTIFS('Content Map'!$C$2:$C$150,$A19,'Content Map'!$F$2:$F$150,F$16) -> 0 | G19: =SUM(B19:F19) -> 4
A20: Sector page | B20: =COUNTIFS('Content Map'!$C$2:$C$150,$A20,'Content Map'!$F$2:$F$150,B$16) -> 0 | C20: =COUNTIFS('Content Map'!$C$2:$C$150,$A20,'Content Map'!$F$2:$F$150,C$16) -> 7 | D20: =COUNTIFS('Content Map'!$C$2:$C$150,$A20,'Content Map'!$F$2:$F$150,D$16) -> 0 | E20: =COUNTIFS('Content Map'!$C$2:$C$150,$A20,'Content Map'!$F$2:$F$150,E$16) -> 0 | F20: =COUNTIFS('Content Map'!$C$2:$C$150,$A20,'Content Map'!$F$2:$F$150,F$16) -> 0 | G20: =SUM(B20:F20) -> 7
A21: Case study | B21: =COUNTIFS('Content Map'!$C$2:$C$150,$A21,'Content Map'!$F$2:$F$150,B$16) -> 1 | C21: =COUNTIFS('Content Map'!$C$2:$C$150,$A21,'Content Map'!$F$2:$F$150,C$16) -> 1 | D21: =COUNTIFS('Content Map'!$C$2:$C$150,$A21,'Content Map'!$F$2:$F$150,D$16) -> 0 | E21: =COUNTIFS('Content Map'!$C$2:$C$150,$A21,'Content Map'!$F$2:$F$150,E$16) -> 0 | F21: =COUNTIFS('Content Map'!$C$2:$C$150,$A21,'Content Map'!$F$2:$F$150,F$16) -> 0 | G21: =SUM(B21:F21) -> 2
A22: Download / white paper | B22: =COUNTIFS('Content Map'!$C$2:$C$150,$A22,'Content Map'!$F$2:$F$150,B$16) -> 1 | C22: =COUNTIFS('Content Map'!$C$2:$C$150,$A22,'Content Map'!$F$2:$F$150,C$16) -> 2 | D22: =COUNTIFS('Content Map'!$C$2:$C$150,$A22,'Content Map'!$F$2:$F$150,D$16) -> 0 | E22: =COUNTIFS('Content Map'!$C$2:$C$150,$A22,'Content Map'!$F$2:$F$150,E$16) -> 4 | F22: =COUNTIFS('Content Map'!$C$2:$C$150,$A22,'Content Map'!$F$2:$F$150,F$16) -> 0 | G22: =SUM(B22:F22) -> 7
A23: Person profile | B23: =COUNTIFS('Content Map'!$C$2:$C$150,$A23,'Content Map'!$F$2:$F$150,B$16) -> 0 | C23: =COUNTIFS('Content Map'!$C$2:$C$150,$A23,'Content Map'!$F$2:$F$150,C$16) -> 12 | D23: =COUNTIFS('Content Map'!$C$2:$C$150,$A23,'Content Map'!$F$2:$F$150,D$16) -> 3 | E23: =COUNTIFS('Content Map'!$C$2:$C$150,$A23,'Content Map'!$F$2:$F$150,E$16) -> 13 | F23: =COUNTIFS('Content Map'!$C$2:$C$150,$A23,'Content Map'!$F$2:$F$150,F$16) -> 0 | G23: =SUM(B23:F23) -> 28
A24: News article | B24: =COUNTIFS('Content Map'!$C$2:$C$150,$A24,'Content Map'!$F$2:$F$150,B$16) -> 11 | C24: =COUNTIFS('Content Map'!$C$2:$C$150,$A24,'Content Map'!$F$2:$F$150,C$16) -> 1 | D24: =COUNTIFS('Content Map'!$C$2:$C$150,$A24,'Content Map'!$F$2:$F$150,D$16) -> 4 | E24: =COUNTIFS('Content Map'!$C$2:$C$150,$A24,'Content Map'!$F$2:$F$150,E$16) -> 22 | F24: =COUNTIFS('Content Map'!$C$2:$C$150,$A24,'Content Map'!$F$2:$F$150,F$16) -> 0 | G24: =SUM(B24:F24) -> 38
A25: Event / course | B25: =COUNTIFS('Content Map'!$C$2:$C$150,$A25,'Content Map'!$F$2:$F$150,B$16) -> 0 | C25: =COUNTIFS('Content Map'!$C$2:$C$150,$A25,'Content Map'!$F$2:$F$150,C$16) -> 0 | D25: =COUNTIFS('Content Map'!$C$2:$C$150,$A25,'Content Map'!$F$2:$F$150,D$16) -> 0 | E25: =COUNTIFS('Content Map'!$C$2:$C$150,$A25,'Content Map'!$F$2:$F$150,E$16) -> 5 | F25: =COUNTIFS('Content Map'!$C$2:$C$150,$A25,'Content Map'!$F$2:$F$150,F$16) -> 0 | G25: =SUM(B25:F25) -> 5
A26: Media | B26: =COUNTIFS('Content Map'!$C$2:$C$150,$A26,'Content Map'!$F$2:$F$150,B$16) -> 0 | C26: =COUNTIFS('Content Map'!$C$2:$C$150,$A26,'Content Map'!$F$2:$F$150,C$16) -> 0 | D26: =COUNTIFS('Content Map'!$C$2:$C$150,$A26,'Content Map'!$F$2:$F$150,D$16) -> 1 | E26: =COUNTIFS('Content Map'!$C$2:$C$150,$A26,'Content Map'!$F$2:$F$150,E$16) -> 1 | F26: =COUNTIFS('Content Map'!$C$2:$C$150,$A26,'Content Map'!$F$2:$F$150,F$16) -> 0 | G26: =SUM(B26:F26) -> 2
A27: Contact / form | B27: =COUNTIFS('Content Map'!$C$2:$C$150,$A27,'Content Map'!$F$2:$F$150,B$16) -> 0 | C27: =COUNTIFS('Content Map'!$C$2:$C$150,$A27,'Content Map'!$F$2:$F$150,C$16) -> 3 | D27: =COUNTIFS('Content Map'!$C$2:$C$150,$A27,'Content Map'!$F$2:$F$150,D$16) -> 0 | E27: =COUNTIFS('Content Map'!$C$2:$C$150,$A27,'Content Map'!$F$2:$F$150,E$16) -> 1 | F27: =COUNTIFS('Content Map'!$C$2:$C$150,$A27,'Content Map'!$F$2:$F$150,F$16) -> 0 | G27: =SUM(B27:F27) -> 4
A28: Homepage slide | B28: =COUNTIFS('Content Map'!$C$2:$C$150,$A28,'Content Map'!$F$2:$F$150,B$16) -> 0 | C28: =COUNTIFS('Content Map'!$C$2:$C$150,$A28,'Content Map'!$F$2:$F$150,C$16) -> 1 | D28: =COUNTIFS('Content Map'!$C$2:$C$150,$A28,'Content Map'!$F$2:$F$150,D$16) -> 1 | E28: =COUNTIFS('Content Map'!$C$2:$C$150,$A28,'Content Map'!$F$2:$F$150,E$16) -> 9 | F28: =COUNTIFS('Content Map'!$C$2:$C$150,$A28,'Content Map'!$F$2:$F$150,F$16) -> 0 | G28: =SUM(B28:F28) -> 11
... A30: Test / duplicate | B30: =COUNTIFS('Content Map'!$C$2:$C$150,$A30,'Content Map'!$F$2:$F$150,B$16) -> 0 | C30: =COUNTIFS('Content Map'!$C$2:$C$150,$A30,'Content Map'!$F$2:$F$150,C$16) -> 0 | D30: =COUNTIFS('Content Map'!$C$2:$C$150,$A30,'Content Map'!$F$2:$F$150,D$16) -> 0 | E30: =COUNTIFS('Content Map'!$C$2:$C$150,$A30,'Content Map'!$F$2:$F$150,E$16) -> 6 | F30: =COUNTIFS('Content Map'!$C$2:$C$150,$A30,'Content Map'!$F$2:$F$150,F$16) -> 0 | G30: =SUM(B30:F30) -> 6
A31: Total | B31: =SUM(B17:B30) -> 13 | C31: =SUM(C17:C30) -> 36 | D31: =SUM(D17:D30) -> 10 | E31: =SUM(E17:E30) -> 66 | F31: =SUM(F17:F30) -> 0 | G31: =SUM(G17:G30) -> 125
A33: Build progress | B33: Pages | C33: % of total
A34: Not started | B34: =COUNTIF('Content Map'!$M$2:$M$150,A34) -> 125 | C34: =IF($B$4=0,0,B34/$B$4) -> 1
A35: In progress | B35: =COUNTIF('Content Map'!$M$2:$M$150,A35) -> 0 | C35: =IF($B$4=0,0,B35/$B$4) -> 0
A36: In review | B36: =COUNTIF('Content Map'!$M$2:$M$150,A36) -> 0 | C36: =IF($B$4=0,0,B36/$B$4) -> 0
A37: Approved | B37: =COUNTIF('Content Map'!$M$2:$M$150,A37) -> 0 | C37: =IF($B$4=0,0,B37/$B$4) -> 0
A38: Live | B38: =COUNTIF('Content Map'!$M$2:$M$150,A38) -> 0 | C38: =IF($B$4=0,0,B38/$B$4) -> 0
A40: Claire sign-off complete | B40: =COUNTIF('Content Map'!$L$2:$L$150,"Yes") -> 0
A41: Redirects set up | B41: =COUNTIF('Content Map'!$N$2:$N$150,"Yes") -> 0
A42: Redirects as % of pages | B42: =IF($B$4=0,0,B41/$B$4) -> 0
A43: Pages still to decide (Review) | B43: =B13 -> 0
A45: Traffic check | B45: Pages | C45: 12m clicks | D45: 12m views
A46: Migrate as is | B46: =COUNTIF('Content Map'!$F$2:$F$150,A46) -> 13 | C46: =SUMIFS('Content Map'!$H$2:$H$150,'Content Map'!$F$2:$F$150,A46) -> 107 | D46: =SUMIFS('Content Map'!$I$2:$I$150,'Content Map'!$F$2:$F$150,A46) -> 417
A47: Rewrite | B47: =COUNTIF('Content Map'!$F$2:$F$150,A47) -> 36 | C47: =SUMIFS('Content Map'!$H$2:$H$150,'Content Map'!$F$2:$F$150,A47) -> 357 | D47: =SUMIFS('Content Map'!$I$2:$I$150,'Content Map'!$F$2:$F$150,A47) -> 5271
...

Sheet Guide
A1: How to use this workbook
A3: Where the suggestions came from | B3: The suggested actions and notes are a first pass based on URL patterns and page titles only. I have not seen the page content or the traffic data, so please treat them as a starting point for Ian, Claire and you to confirm.
A4: Pale yellow cells | B4: These are the cells for you to fill in: Agreed action, New URL, Owner and Claire sign-off. Everything else is pre-filled or calculated.
A5: Suggested vs agreed action | B5: Column D is the suggestion. Choose from the dropdown in column E when a decision is made. Column F (Working action) shows the agreed action if there is one, otherwise the suggestion, and feeds the Summary tab.
A6: Traffic columns | B6: Clicks (Google Search Console) and views (GA4) are pulled in by formula from the GSC and GA4 tabs. Both cover 28 Sep 2025 to 28 Sep 2026 (GSC starts 26 Sep 2025). A zero means the page had no data in the export. To refresh, paste new exports over the GSC and GA4 tabs, keeping the same columns.
A7: Pages added from analytics | B7: Eleven rows were added because they appeared in GA4 or Search Console but were missing from the original URL list (forms, the training course page, PDFs and two raw node URLs). Their notes start with "Not in the original URL list".
A8: Left out on purpose | B8: Admin and system URLs (login, user pages, search, 403/404 pages), list pagination, image files and a few legacy .asp probes were left out as they need no rebuild. Ask whoever runs the server whether any legacy URLs need redirects.
A9: Adding pages | B9: Add new rows below the last one (the formulas, dropdowns and Summary counts run to row 150).
A10: Migrate as is | B10: Content moves across with light edits, rebuilt in the Hutton template.
A11: Rewrite | B11: Content needs reworking for the Hutton structure, tone or keywords.
A12: Merge | B12: Content folds into another page. Put the destination in the New URL column.
A13: Retire | B13: Page is not rebuilt. It still needs a 301 redirect to the closest relevant new page (never just the homepage).
A14: Review | B14: No decision yet. Check traffic and content, then decide.
... A16: Example row | B16: Old URL: https://www.lipid.co.uk/services/stability | Agreed action: Rewrite | New URL: https://www.hutton.ac.uk/[agreed path]/stability | Owner: Harvey | Claire sign-off: Yes | Status: Approved | Redirect set up: No. (The path is a placeholder until the Hutton structure is agreed.)

Sheet GSC
A1: URL | B1: Clicks (12m) | C1: Impressions (12m)
A2: https://www.lipid.co.uk/ | B2: 257 | C2: 5153
A3: https://www.lipid.co.uk/bill-christie-0 | B3: 72 | C3: 1615
A4: https://www.lipid.co.uk/about-us | B4: 43 | C4: 1670
A5: https://www.lipid.co.uk/bill-christie | B5: 39 | C5: 1580
A6: https://www.lipid.co.uk/news/egg-centric-nutrition-humans | B6: 37 | C6: 17824
A7: https://www.lipid.co.uk/news/oxidised-fish-oil-problem | B7: 23 | C7: 8382
A8: https://www.lipid.co.uk/services/training-course | B8: 23 | C8: 417
A9: https://www.lipid.co.uk/claire-traynor | B9: 20 | C9: 447
A10: https://www.lipid.co.uk/sites/www.lipid.co.uk/files/2018-12/Mallakin RLO paper - 2018.pdf | B10: 17 | C10: 1439
A11: https://www.lipid.co.uk/services/analyses | B11: 16 | C11: 1388
A12: https://www.lipid.co.uk/news/professor-frank-d-gunstone | B12: 13 | C12: 460
A13: https://www.lipid.co.uk/news/oxidised-fish | B13: 11 | C13: 3574
... A107: https://www.lipid.co.uk/sites/www.lipid.co.uk/files/2025-01/GOED cert image.jpg | B107: 0 | C107: 1

Sheet GA4
A1: Page path | B1: Views (12m) | C1: Active users
A2: / | B2: 2698 | C2: 2279
A3: /services | B3: 372 | C3: 255
A4: /news | B4: 276 | C4: 262
A5: /about-us | B5: 274 | C5: 205
A6: /services/analyses | B6: 227 | C6: 153
A7: /contact-us | B7: 224 | C7: 167
A8: /sectors | B8: 211 | C8: 126
A9: /new-customer-form | B9: 176 | C9: 70
A10: /quality | B10: 137 | C10: 96
A11: /samples | B11: 118 | C11: 96
A12: /bill-christie-0 | B12: 106 | C12: 71
A13: /news/oxidised-fish-oil-problem | B13: 100 | C13: 92
... A123: /subscribe | B123: 1 | C123: 1
